Workbook

Sheet Clientes Novos
B1: Nome | C1: Conta | D1: Escritório | E1: UF | F1: Assessor | G1: APP | H1: Observações | I1: Carteira | J1: TX. de Gestão | K1: Benchmark | L1: TX. Perf. | M1: CPF/CNPJ | N1: Telefone | O1: E-mail | P1: Aniversário | Q1: UF cliente | R1: Suitability | S1: Observações
A2: BTG | B2: Franklin Silva de Novais | C2: 004826721 | D2: Investeseg | E2: BA | F2: Murilo Silva | G2: PIPE | H2: Aguardando FA | I2: CON | J2: 0.012 | K2: CDI | L2: 0.1 | M2: 017.737.005-02 | N2: 71 99907-7741 | O2: franknovais@hotmail.com | P2: 31599 | Q2: BA | R2: Moderado | S2: TEM OBS
A3: BTG | B3: Andre Albuquerque Villas | C3: 003537823 | D3: Expert | E3: GO | F3: Felipe Ouriveis | G3: PIPE | H3: Aguardando Vinculação de conta | I3: INC | J3: 0.012 | K3: ------ | L3: 0 | M3: 761.414.111-34 | N3: 67 99982-4900 | O3: aavillas75@gmail.com | P3: 27556 | Q3: MS | R3: Moderado | S3: Manter 30% em liquidez, por enquanto.
A4: BTG | B4: Ana Paula Herrero | C4: 008475532 | D4: Miura | E4: SUL | F4: Victor | G4: PIPE | H4: Aguardando Cobrança de Taxas | I4: INC | J4: 0.012 | K4: ------ | L4: 0 | N4: (43) 99922-6163 | O4: anapaula_herrero@hotmail.com | R4: Conservador
A5: Pershing | B5: Rubens Dias da Costa Neto Souza | C5: xxxxxxx | D5: Bluemetrix | E5: GO | F5: Felipe Rios | G5: PIPE | H5: Em Análise pela Corretora | I5: INT | J5: 0.016 | K5: ------ | L5: 0 | M5: 755.745.001-91 | N5: 62 99845-8856 | O5: rubensdnetos@gmail.com | P5: 36178 | Q5: GO | R5: Arrojado
A6: BTG | B6: Cardiointerv S/S | C6: xxxxxxx | D6: VcInvest | E6: GO | F6: Bruno | G6: PIPE | H6: Em Análise pela Corretora | I6: INC | J6: 0.012 | K6: ------ | L6: 0 | M6: 13.552.357/0001-24 | N6: 62 98115-0222 | O6: afreitasjr@msn.com | P6: 40653 | Q6: GO | R6: Moderado | S6: Desistiu
A7: BTG | B7: ARGIO SERVICOS LTDA | C7: xxxxxxx | D7: Bluemetrix | E7: GO | F7: felipe | G7: PIPE | H7: Em Análise pela Corretora | I7: INC | J7: 0.012 | K7: ------ | L7: 0 | M7: 54.744.253/0001-07 | N7: 62 98285-8250 | O7: Argioservicos@gmail.com | P7: 45398 | Q7: GO | R7: Conservador
A8: BTG | B8: Aline Kanyo De Queiroz e/ou Rafael Crispim Gonçalves | C8: xxxxxxx | D8: Bluemetrix | E8: DF | F8: Thiago | G8: PIPE | H8: Em Análise pela Corretora | I8: MONT | J8: 0 | K8: ------ | L8: 0 | M8: 001.773.141-09 | N8: 61999777420 | O8: alinekanyo@gmail.com | P8: 31275 | Q8: DF | R8: Conservador
A9: Ágora | B9: Ricardo Roberto Arquitetura LTDA | C9: xxxxxxx | D9: MI Smart | E9: DF | F9: Mariana | G9: PIPE | H9: Em Análise pela Corretora | I9: CORP | J9: 0.01 | K9: ------ | L9: 0 | M9: 29.450.428/0001-18 | N9: 61 99413-7963 | O9: ricardo.roberto.df@gmail.com | P9: 43116 | Q9: DF | R9: Conservador | S9: Deixar tudo em liquidez
A10: XP | B10: Adriana Carneiro Macedo | C10: 19831186 | D10: Investeseg | E10: BA | F10: Murilo Silva | G10: PIPE | H10: Pendente de Aceite do Termo | I10: INC | J10: 0.012 | K10: ------ | L10: 0 | M10: 940.673.765-53 | N10: 11 99732-6602 | O10: adrimacedo@hotmail.com | P10: 28251 | Q10: BA | R10: Moderado
A11: Interactive Brokers | B11: Wellington Coelho de Souza Junior | C11: xxxxxxx | D11: Expert | E11: GO | F11: Felipe Ouriveis | G11: PIPE | H11: Pendente assinaturas | I11: INT | J11: 0.0115 | K11: ------ | L11: 0 | M11: 730.614.501-06 | N11: 67 99256-9156 | O11: wellingtoncsjr@hotmail.com | P11: 31473 | Q11: MS | R11: Moderado
A12: BTG | B12: Daniel Francisco dos Santos e Silva | C12: 005275706 | D12: Expert | E12: GO | F12: Felipe Ouriveis | G12: PIPE | H12: Pendente assinaturas | I12: CON | J12: 0.012 | K12: ------ | L12: 0 | M12: 904.565.561-68 | N12: 61 98250-8228 | O12: danisilv@gmail.com | P12: 29409 | Q12: DF | R12: Moderado
A13: BTG | B13: Fabiano Cury Rodrigues | C13: xxxxxxx | D13: VcInvest | E13: GO | F13: Bruno | G13: PIPE | H13: Pendente assinaturas | I13: INC | J13: 0.012 | K13: ------ | L13: 0 | M13: 877.730.071-87 | N13: 62 99219-7777 | O13: fabianocr@gmail.com | P13: 28669 | Q13: GO | R13: Moderado | S13: 20 a 30% de liquidez mais rápida, prazo máximo de 2 anos em ativos da carteira
A14: BTG | B14: Leandro Augusto De Araujo Cunha T Bueno e/ou Naiara Cunha Teixeira Bueno | C14: xxxxxxx | D14: Bluemetrix | E14: DF | F14: Thiago | G14: PIPE | H14: Pendente assinaturas | I14: INC | J14: 0.0085 | K14: ------ | L14: 0 | M14: 342.258.488 92 | S14: Vencido
A15: BTG | B15: Marcos Roberto Grimm | C15: 004109781 | D15: Expert | E15: GO | F15: Felipe Ouriveis | G15: PIPE | H15: Pendente assinaturas | I15: INC | J15: 0.012 | K15: ------ | L15: 0 | M15: 404.497.001-78 | N15: 67 99901-9497 | O15: marcosgrimm.mg@gmail.com | P15: 24369 | Q15: MS | S15: Manter 50% da carteira em liquidez D0 ou D+1, por enquanto e trabalhar com ativos mais curtos.
A16: BTG | B16: Sergio Alberto Ramos e/ou Elisa Kioko Matsumoto Ramos | C16: xxxxxxx | D16: Expert | E16: GO | F16: Felipe Ouriveis | G16: PIPE | H16: Pendente assinaturas | I16: INC | J16: 0.012 | K16: ------ | L16: 0 | M16: 056.674.278-00 | N16: 67 98425-2820 | O16: sar.ramos@hotmail.com | P16: 23566 | Q16: MS | R16: Conservador
A17: XP | B17: Ethel Ferreira Poll | C17: xxxxxxx | D17: Investeseg | E17: BA | F17: Carol | G17: PIPE | H17: Pendente assinaturas | I17: INC | J17: 0.012 | K17: ------ | L17: 0 | M17: 585.217.470-04 | N17: 71 99965-3709 | O17: ethelpoll@hotmail.com | P17: 26036 | Q17: BA | R17: Moderado
A18: BTG | B18: OLIVEIRA COMERCIO DO VESTUARIO LTDA | C18: xxxxxxx | D18: Bluemetrix | E18: GO | F18: Fabricio | G18: PIPE | H18: Pendente assinaturas | I18: INC | J18: 0.012 | K18: ------ | L18: 0 | M18: 27.265.200/0001-22 | N18: 62 98244-9400 | O18: dellufitness@gmail.com | P18: 42803 | Q18: GO | R18: Moderado

Sheet BTG
A1: Backoffice | G1: Mesa de Operação | H1: Backoffice/ Mesa | J1: Backoffice | Q1: Mesa de Operação | R1: Backoffice | S1: Anbima | AF1: Financeiro | AG1: Financeiro | AH1: Financeiro | AI1: Financeiro | AJ1: Financeiro | AK1: Financeiro | AL1: Financeiro | AM1: Financeiro | AN1: Financeiro | AO1: Financeiro | AP1: Financeiro | AQ1: Financeiro | AR1: Financeiro | AS1: Financeiro | AT1: Financeiro | AU1: Financeiro | AV1: Financeiro | AW1: Financeiro | AX1: Financeiro | AY1: Financeiro | AZ1: Financeiro | BA1: Financeiro | BB1: Financeiro | BC1: Financeiro | BD1: Financeiro | BE1: Financeiro | BF1: Financeiro | BG1: Financeiro | BH1: Financeiro | BI1: Financeiro | BJ1: Financeiro | BK1: Financeiro | BL1: Financeiro | BM1: Financeiro | BN1: Financeiro | BO1: Financeiro | BP1: Financeiro | BQ1: Financeiro | BR1: Financeiro | BS1: Financeiro | BT1: Financeiro | BU1: Financeiro | BV1: Financeiro | BW1: Financeiro | BX1: Financeiro | BY1: Financeiro
A2: Corretora | B2: Cliente | C2: Conta | D2: Escritório | E2: UF | F2: Assessor | G2: Operador | H2: Status | I2: Situação | J2: Exceção | K2: Início da Gestão | L2: Data distrato | M2: Carteira | N2: Taxa de Gestão | O2: Benchmark TX. Perf. | P2: TX. Perf. | Q2: Observações | R2: Observações Backoffice | S2: PF/ PJ | T2: CPF/CNPJ | U2: Telefone | V2: E-mail | W2: Aniversário | X2: UF cliente | Y2: Status Anbima | Z2: Perfil de risco da carteira | AA2: Perfil de risco do investidor | AB2: Classificação do Investidor | AC2: Grupo Econômico (Região) | AD2: Data Primeiro Aporte | AE2: Código Anbima | AF2: 31/10/2022 | AG2: 30/11/2022 | AH2: 30/12/2022 | AI2: 31/01/2023 | AJ2: 28/02/2023 | AK2: 31/03/2023 | AL2: 28/04/2023 | AM2: 31/05/2023 | AN2: 30/06/2023 | AO2: 31/07/2023 | AP2: 31/08/2023 | AQ2: 29/09/2023 | AR2: 31/10/2023 | AS2: 30/11/2023 | AT2: 29/12/2023 | AU2: 31/01/2024 | AV2: 29/02/2024 | AW2: 28/03/2024 | AX2: 30/04/2024 | AY2: 31/05/2024 | AZ2: 28/06/2024 | BA2: 31/07/2024 | BB2: 30/08/2024 | BC2: 30/09/2024 | BD2: 31/10/2024 | BE2: 29/11/2024 | BF2: 31/12/2024 | BG2: 31/01/2025 | BH2: 28/02/2025 | BI2: 31/03/2025 | BJ2: 30/04/2025 | BK2: 30/05/2025 | BL2: 30/06/2025 | BM2: 31/07/2025 | BN2: 31/08/2025 | BO2: 30/09/2025 | BP2: 31/10/2025 | BQ2: 30/11/2025 | BR2: 31/12/2025 | BS2: 31/01/2026 | BT2: 28/02/2026 | BU2: 31/03/2026 | BV2: 30/04/2026 | BW2: 31/05/2026 | BX2: 30/06/2026 | BY2: Julho (D-1)
A3: BTG | B3: Adao Baum Penha | C3: 026476960 | D3: Miura | E3: SUL | F3: Lucas Zambrin | G3: =IFS($BS$4:$BS$1280<=250000,"David",$BS$4:$BS$1280<=800000,"Gabriel", $BS$4:$BS$1280>800000,"Marcus") -> #VALUE! | H3: Ativo | I3: ------ | J3: =IF(Q3=0,"Não","Sim") -> Não | K3: 46217 | M3: MOD | N3: 0.015 | O3: CDI | P3: 0.1 | S3: PF | T3: 086.751.079-00 | U3: 43 99962-0426 | V3: adaobaum@gmail.com | W3: 33735 | X3: PR | Y3: =IFS(H:H="Encerrado","Encerrado",COUNTBLANK(AZ3:BK3)>0,"Ativo",SUM(AZ3:BK3)=0,"Inativo",SUM(AZ3:BK3)>0,"Ativo") -> Ativo | AA3: Moderado | BX3: 0 | BY3: {=XLOOKUP(C3,'PL TOTAL D0'!$A$3:$A$1991,'PL TOTAL D0'!$C$3:$C$1991,"")} -> 1151901.7
A4: BTG | B4: Adele Rossi Heusi | C4: 004575632 | D4: Voga | E4: DF | F4: Theo Ramos Moutinho | G4: =IFS($BS$4:$BS$1280<=250000,"David",$BS$4:$BS$1280<=800000,"Gabriel", $BS$4:$BS$1280>800000,"Marcus") -> David | H4: Encerrado | I4: ------ | J4: =IF(Q4=0,"Não","Sim") -> Não | K4: 45105 | L4: 45552 | M4: CON | N4: 0.012 | O4: CDI | P4: 0.1 | R4: Cliente solicitou troca de assessoria (08/08/2024) | S4: PF | T4: 334.053.601-53 | X4: DF | Y4: =IFS(H:H="Encerrado","Encerrado",COUNTBLANK(AZ4:BK4)>0,"Ativo",SUM(AZ4:BK4)=0,"Inativo",SUM(AZ4:BK4)>0,"Ativo") -> Encerrado | AB4: Qualificado | AD4: 45105 | AE4: 49075100007179 | AN4: 11645.25 | AO4: 101705.9 | AP4: 87680.81 | AQ4: 97773.76 | AR4: 94701.07 | AS4: 97855.43 | AT4: 93543.64 | AU4: 346111.38 | AV4: 469765.42 | AW4: 504924.71 | AX4: 496452.34 | AY4: 471980.3 | AZ4: 412836.6 | BA4: 399202.4 | BB4: 0 | BC4: 0 | BD4: 0 | BE4: 0 | BF4: 0 | BG4: 0 | BH4: 0 | BI4: 0 | BJ4: 0 | BK4: 0 | BL4: 0 | BM4: 0 | BN4: 0 | BO4: 0 | BP4: 0 | BQ4: 0 | BR4: 0 | BS4: 0 | BT4: 0 | BU4: 0 | BW4: 0 | BX4: 0 | BY4: {=XLOOKUP(C4,'PL TOTAL D0'!$A$3:$A$1991,'PL TOTAL D0'!$C$3:$C$1991,"")}
A5: BTG | B5: Adriana Amorin Monteiro | C5: 002471066 | D5: Poupinvista | E5: DF | F5: Bruno Rodrigues | G5: =IFS($BS$4:$BS$1280<=250000,"David",$BS$4:$BS$1280<=800000,"Gabriel", $BS$4:$BS$1280>800000,"Marcus") -> Gabriel | H5: Ativo | I5: ------ | J5: =IF(Q5=0,"Não","Sim") -> Não | K5: 45923 | M5: INC | N5: 0.012 | O5: ------ | P5: 0 | S5: PF | T5: 622.372.763-15 | U5: 81 98900-0164 | V5: drikas.amorim@gmail.com | W5: 28556 | X5: PE | Y5: =IFS(H:H="Encerrado","Encerrado",COUNTBLANK(AZ5:BK5)>0,"Ativo",SUM(AZ5:BK5)=0,"Inativo",SUM(AZ5:BK5)>0,"Ativo") -> Ativo | AA5: Moderado | AD5: 45923 | AE5: 49075100019428 | BO5: 391712.81 | BP5: 403957.9 | BQ5: 406166.3 | BR5: 548723.1 | BS5: 550961.42 | BT5: 536101.1 | BU5: 494037.2 | BV5: 490251.4 | BW5: 472634.2 | BX5: 478704.69 | BY5: {=XLOOKUP(C5,'PL TOTAL D0'!$A$3:$A$1991,'PL TOTAL D0'!$C$3:$C$1991,"")} -> 504296.39
A6: BTG | B6: Adriana Dos Santos Alcantara | C6: 026362731 | D6: Bluemetrix | E6: DF | F6: Thiago Canabrava | G6: =IFS($BS$4:$BS$1280<=250000,"David",$BS$4:$BS$1280<=800000,"Gabriel", $BS$4:$BS$1280>800000,"Marcus") -> David | H6: Ativo | I6: ------ | J6: =IF(Q6=0,"Não","Sim") -> Não | K6: 46216 | M6: INC | N6: 0.012 | O6: ------ | P6: 0 | S6: PF | T6: 540.112.301-97 | U6: 61 98116-7402 | V6: Adriana.Alcantara2020@outlook.com | W6: 24/11/0170 | X6: DF | Y6: =IFS(H:H="Encerrado","Encerrado",COUNTBLANK(AZ6:BK6)>0,"Ativo",SUM(AZ6:BK6)=0,"Inativo",SUM(AZ6:BK6)>0,"Ativo") -> Ativo | AA6: Moderado | BX6: 0 | BY6: {=XLOOKUP(C6,'PL TOTAL D0'!$A$3:$A$1991,'PL TOTAL D0'!$C$3:$C$1991,"")} -> 30201.01
A7: BTG | B7: Adriana Dos Santos Alcantara | C7: 036660678 | D7: Bluemetrix | E7: DF | F7: Thiago Canabrava | G7: =IFS($BS$4:$BS$1280<=250000,"David",$BS$4:$BS$1280<=800000,"Gabriel", $BS$4:$BS$1280>800000,"Marcus") -> David | H7: Pode Operar | I7: ------ | J7: =IF(Q7=0,"Não","Sim") -> Não | K7: 46234 | M7: INC | N7: 0.012 | O7: ------ | P7: 0 | S7: PF | T7: 540.112.301-97 | U7: 61 98116-7402 | V7: Adriana.Alcantara2020@outlook.com | W7: 24/11/0170 | X7: DF | Y7: =IFS(H:H="Encerrado","Encerrado",COUNTBLANK(AZ7:BK7)>0,"Ativo",SUM(AZ7:BK7)=0,"Inativo",SUM(AZ7:BK7)>0,"Ativo") -> Ativo | AA7: Moderado
A8: BTG | B8: Adriana Garcia Rosa | C8: 005715733 | D8: Bluemetrix | E8: GO | F8: Vivian | G8: =IFS($BS$4:$BS$1280<=250000,"David",$BS$4:$BS$1280<=800000,"Gabriel", $BS$4:$BS$1280>800000,"Marcus") -> David | H8: Encerrado | I8: ------ | J8: =IF(Q8=0,"Não","Sim") -> Não | K8: 45575 | L8: 45873 | M8: INC | N8: 0.012 | O8: ------ | P8: 0 | R8: Distrato Unilateral | S8: PF | T8: 778.127.601-97 | X8: GO | Y8: =IFS(H:H="Encerrado","Encerrado",COUNTBLANK(AZ8:BK8)>0,"Ativo",SUM(AZ8:BK8)=0,"Inativo",SUM(AZ8:BK8)>0,"Ativo") -> Encerrado | AA8: Conservador | AD8: 45575 | AE8: 49075100015937 | BD8: 25129.32 | BE8: 28365.69 | BF8: 42735.29 | BG8: 43359.18 | BH8: 43783.43 | BI8: 46235.25 | BJ8: 43169.62 | BK8: 47521.44 | BL8: 0 | BM8: 0 | BN8: 0 | BO8: 0 | BP8: 0 | BQ8: 0 | BR8: 0 | BS8: 0 | BT8: 0 | BU8: 0 | BV8: 0 | BW8: 0 | BX8: 0 | BY8: {=XLOOKUP(C8,'PL TOTAL D0'!$A$3:$A$1991,'PL TOTAL D0'!$C$3:$C$1991,"")}
A9: BTG | B9: Adriana Sobral Lourenco | C9: 004240400 | D9: Altum | E9: DF | F9: Alexandre Xavier | G9: =IFS($BS$4:$BS$1280<=250000,"David",$BS$4:$BS$1280<=800000,"Gabriel", $BS$4:$BS$1280>800000,"Marcus") -> David | H9: Ativo | I9: ------ | J9: =IF(Q9=0,"Não","Sim") -> Não | K9: 45448 | M9: CON | N9: 0.012 | O9: CDI | P9: 0.1 | S9: PF | T9: 607.674.302-63 | U9: 5561981347034 | V9: drisobrallourenco@gmail.com | W9: 27638 | X9: DF | Y9: =IFS(H:H="Encerrado","Encerrado",COUNTBLANK(AZ9:BK9)>0,"Ativo",SUM(AZ9:BK9)=0,"Inativo",SUM(AZ9:BK9)>0,"Ativo") -> Ativo | AA9: Moderado | AB9: Qualificado | AD9: 45448 | AE9: 49075100015023 | AZ9: 121700.5 | BA9: 123070.4 | BB9: 123754.77 | BC9: 127558.92 | BD9: 143233.67 | BE9: 142815.33 | BF9: 153533.2 | BG9: 164010.93 | BH9: 168227.15 | BI9: 202632.33 | BJ9: 206574.72 | BK9: 178281.56 | BL9: 182801.31 | BM9: 185347.86 | BN9: 189197.2 | BO9: 193123.36 | BP9: 204372.5 | BQ9: 206026.5 | BR9: 211050.1 | BS9: 213379.81 | BT9: 215053.2 | BU9: 217325.5 | BV9: 219246.2 | BW9: 219899.3 | BX9: 220858.3 | BY9: {=XLOOKUP(C9,'PL TOTAL D0'!$A$3:$A$1991,'PL TOTAL D0'!$C$3:$C$1991,"")} -> 216111.18
A10: BTG | B10: Adriano Antônio Alves | C10: 004451996 | D10: Bluemetrix | E10: GO | F10: Vivian | G10: =IFS($BS$4:$BS$1280<=250000,"David",$BS$4:$BS$1280<=800000,"Gabriel", $BS$4:$BS$1280>800000,"Marcus") -> David | H10: Inativo | I10: Sem Saldo | J10: =IF(Q10=0,"Não","Sim") -> Não | K10: 45036 | M10: INC | N10: 0.012 | O10: ------ | P10: 0 | S10: PF | T10: 548.976.961-00 | U10: 62984152005 | V10: adriano@orais.com.br | W10: 26149 | X10: GO | Y10: =IFS(H:H="Encerrado","Encerrado",COUNTBLANK(AZ10:BK10)>0,"Ativo",SUM(AZ10:BK10)=0,"Inativo",SUM(AZ10:BK10)>0,"Ativo") -> Ativo | AB10: Qualificado | AD10: 45036 | AE10: 49075100008310 | AK10: 0 | AL10: 10017.88 | AM10: 10121.37 | AN10: 10216.79 | AO10: 10266.22 | AP10: 10256.52 | AQ10: 10245.37 | AR10: 10303.3 | AS10: 10380.65 | AT10: 10461.92 | AU10: 10552.25 | AV10: 10641.25 | AW10: 10727.74 | AX10: 10819.52 | AY10: 10903.41 | AZ10: 0 | BA10: 0 | BB10: 0.09 | BC10: 0.09 | BD10: 0.09 | BE10: 0.09 | BF10: 0.09 | BG10: 0.09 | BH10: 0.09 | BI10: 0.09 | BJ10: 0 | BK10: 0 | BL10: 0 | BM10: 0 | BN10: 0 | BO10: 0 | BP10: 0 | BQ10: 0 | BR10: 0 | BS10: 0 | BT10: 0 | BU10: 0 | BV10: 0 | BW10: 0 | BX10: 0 | BY10: {=XLOOKUP(C10,'PL TOTAL D0'!$A$3:$A$1991,'PL TOTAL D0'!$C$3:$C$1991,"")}
A11: BTG | B11: Adriano Carvalho Costa | C11: 003916735 | D11: Bluemetrix | E11: GO | F11: Felipe Rios | G11: =IFS($BS$4:$BS$1280<=250000,"David",$BS$4:$BS$1280<=800000,"Gabriel", $BS$4:$BS$1280>800000,"Marcus") -> David | H11: Inativo | I11: Sem Saldo | J11: =IF(Q11=0,"Não","Sim") -> Não | K11: 45474 | M11: INC | N11: 0.012 | O11: ------ | P11: 0 | S11: PF | T11: 006.352.131-84 | U11: 5562999714102 | V11: didasgyn@gmail.com | W11: 31314 | X11: GO | Y11: =IFS(H:H="Encerrado","Encerrado",COUNTBLANK(AZ11:BK11)>0,"Ativo",SUM(AZ11:BK11)=0,"Inativo",SUM(AZ11:BK11)>0,"Ativo") -> Ativo | AA11: Arrojado | AB11: Qualificado | AD11: 45474 | AE11: 49075100015503 | BA11: 0 | BB11: 0 | BC11: 0 | BD11: 0 | BE11: 0 | BF11: 0 | BG11: 0 | BH11: 0 | BI11: 0 | BJ11: 0 | BK11: 0 | BL11: 0 | BM11: 0 | BN11: 0 | BO11: 0 | BP11: 0 | BQ11: 0 | BR11: 0 | BS11: 0 | BT11: 0 | BU11: 0 | BV11: 0 | BW11: 0 | BX11: 0 | BY11: {=XLOOKUP(C11,'PL TOTAL D0'!$A$3:$A$1991,'PL TOTAL D0'!$C$3:$C$1991,"")}
A12: BTG | B12: Adriano de Moraes Arantes | C12: 003039255 | D12: VcInvest | E12: GO | F12: Bruno Ribeiro | G12: =IFS($BS$4:$BS$1280<=250000,"David",$BS$4:$BS$1280<=800000,"Gabriel", $BS$4:$BS$1280>800000,"Marcus") -> David | H12: Ativo | I12: ------ | J12: =IF(Q12=0,"Não","Sim") -> Não | K12: 46174 | M12: INC | N12: 0.012 | O12: ------ | P12: 0 | S12: PF | T12: 784.374.231-04 | U12: 62 99980-8750 | V12: arantesadriano@hotmail.com | W12: 27757 | X12: GO | Y12: =IFS(H:H="Encerrado","Encerrado",COUNTBLANK(AZ12:BK12)>0,"Ativo",SUM(AZ12:BK12)=0,"Inativo",SUM(AZ12:BK12)>0,"Ativo") -> Ativo | AA12: Moderado | AD12: 46203 | BX12: 199096.49 | BY12: {=XLOOKUP(C12,'PL TOTAL D0'!$A$3:$A$1991,'PL TOTAL D0'!$C$3:$C$1991,"")} -> 251715.28
A13: BTG | B13: Adriano Marcio de Oliveira Flausino Filho | C13: 004231371 | D13: Bluemetrix | E13: DF | F13: Bruno Henrique | G13: =IFS($BS$4:$BS$1280<=250000,"David",$BS$4:$BS$1280<=800000,"Gabriel", $BS$4:$BS$1280>800000,"Marcus") -> David | H13: Ativo | I13: ------ | J13: =IF(Q13=0,"Não","Sim") -> Não | K13: 45309 | M13: FUND | N13: 0 | O13: ------ | P13: 0 | S13: PF | T13: 009.594.841-40 | U13: 5561981389093 | V13: amoffilho@gmail.com | W13: 34824 | X13: DF | Y13: =IFS(H:H="Encerrado","Encerrado",COUNTBLANK(AZ13:BK13)>0,"Ativo",SUM(AZ13:BK13)=0,"Inativo",SUM(AZ13:BK13)>0,"Ativo") -> Ativo | AB13: Qualificado | AD13: 45309 | AE13: 49075100013111 | AU13: 1001.72 | AV13: 4019.27 | AW13: 1001.59 | AX13: 2014.05 | AY13: 2604.93 | AZ13: 3315.03 | BA13: 3698.13 | BB13: 4081.22 | BC13: 4615.4 | BD13: 5031.39 | BE13: 5380.13 | BF13: 6021.15 | BG13: 6818.24 | BH13: 7518.39 | BI13: 8204.11 | BJ13: 0 | BK13: 0.29 | BL13: 0.29 | BM13: 0.29 | BN13: 0.29 | BO13: 2015.63 | BP13: 0 | BQ13: 6500 | BR13: 5062.04 | BS13: 5041 | BT13: 2059.92 | BU13: 4595.68 | BV13: 4645.22 | BW13: 1821.17 | BX13: 1835.28 | BY13: {=XLOOKUP(C13,'PL TOTAL D0'!$A$3:$A$1991,'PL TOTAL D0'!$C$3:$C$1991,"")}
A14: BTG | B14: Adson Rodrigues de Souza | C14: 004404342 | D14: Bluemetrix | E14: GO | F14: Vivian | G14: =IFS($BS$4:$BS$1280<=250000,"David",$BS$4:$BS$1280<=800000,"Gabriel", $BS$4:$BS$1280>800000,"Marcus") -> David | H14: Encerrado | I14: ------ | J14: =IF(Q14=0,"Não","Sim") -> Não | K14: 44974 | L14: 45940 | M14: INC | N14: 0.012 | O14: ------ | P14: 0 | S14: PF | T14: 375.046.571-15 | X14: GO | Y14: =IFS(H:H="Encerrado","Encerrado",COUNTBLANK(AZ14:BK14)>0,"Ativo",SUM(AZ14:BK14)=0,"Inativo",SUM(AZ14:BK14)>0,"Ativo") -> Encerrado | AB14: Qualificado | AD14: 44974 | AE14: 49075100003300 | AJ14: 0 | AK14: 831494.82 | AL14: 839282.3 | AM14: 850795.67 | AN14: 861974.11 | AO14: 862874.84 | AP14: 838055.38 | AQ14: 839394.89 | AR14: 844581.11 | AS14: 855717.31 | AT14: 867240.53 | AU14: 875442.71 | AV14: 883735.44 | AW14: 889186.44 | AX14: 891932.67 | AY14: 900933.7 | AZ14: 902936.8 | BA14: 910147.4 | BB14: 929204.87 | BC14: 935280.85 | BD14: 943521.07 | BE14: 951328.95 | BF14: 958000.56 | BG14: 966488.7 | BH14: 972248.01 | BI14: 977734.4 | BJ14: 985579.28 | BK14: 997622.25 | BL14: 1006792.4 | BM14: 0 | BN14: 0 | BO14: 0 | BP14: 0 | BQ14: 0 | BR14: 0 | BS14: 0 | BT14: 0 | BU14: 0 | BV14: 0 | BW14: 0 | BX14: 0 | BY14: {=XLOOKUP(C14,'PL TOTAL D0'!$A$3:$A$1991,'PL TOTAL D0'!$C$3:$C$1991,"")}
A15: BTG | B15: Aécio Araújo Barros | C15: 016322281 | D15: Poupinvista | E15: DF | F15: Bruno Rodrigues | G15: =IFS($BS$4:$BS$1280<=250000,"David",$BS$4:$BS$1280<=800000,"Gabriel", $BS$4:$BS$1280>800000,"Marcus") -> Gabriel | H15: Ativo | I15: ------ | J15: =IF(Q15=0,"Não","Sim") -> Não | K15: 45957 | M15: INC | N15: 0.012 | O15: ------ | P15: 0 | S15: PF | T15: 006.320.061-96 | U15: 61 98542-0349 | V15: aeciohsf@gmail.com | W15: 31347 | X15: DF | Y15: Ativo | AA15: Moderado | AD15: 45972 | AE15: 49075100019746 | BP15: 0 | BQ15: 452427.4 | BR15: 650471.9 | BS15: 677600.62 | BT15: 689496.6 | BU15: 697605.9 | BV15: 708323.7 | BW15: 718819.2 | BX15: 728945.98 | BY15: {=XLOOKUP(C15,'PL TOTAL D0'!$A$3:$A$1991,'PL TOTAL D0'!$C$3:$C$1991,"")} -> 738397.44
A16: BTG | B16: Aguinaldo Figueiredo de Freitas Junior | C16: 005645211 | D16: VcInvest | E16: GO | F16: Bruno Ribeiro | G16: =IFS($BS$4:$BS$1280<=250000,"David",$BS$4:$BS$1280<=800000,"Gabriel", $BS$4:$BS$1280>800000,"Marcus") -> Marcus | H16: Ativo | I16: ------ | J16: =IF(Q16=0,"Não","Sim") -> Não | K16: 45450 | M16: INC | N16: 0.012 | O16: ------ | P16: 0 | S16: PF | T16: 817.848.051-49 | U16: 62981150222 | V16: afreitasjr@msn.com | W16: 28348 | X16: GO | Y16: =IFS(H:H="Encerrado","Encerrado",COUNTBLANK(AZ16:BK16)>0,"Ativo",SUM(AZ16:BK16)=0,"Inativo",SUM(AZ16:BK16)>0,"Ativo") -> Ativo | AA16: Arrojado | AB16: Qualificado | AD16: 45450 | AE16: 49075100015090 | AZ16: 778994.8 | BA16: 1000481 | BB16: 1009940.4 | BC16: 1015213.2 | BD16: 1024360 | BE16: 1032672.2 | BF16: 1041614.6 | BG16: 1252480.7 | BH16: 1264087.8 | BI16: 1277280.9 | BJ16: 1392309.6 | BK16: 1758966.9 | BL16: 1773460.9 | BM16: 1892288.7 | BN16: 2007259 | BO16: 2126336.3 | BP16: 2352474 | BQ16: 2573545 | BR16: 2786134 | BS16: 2814450.8 | BT16: 2861943 | BU16: 3082585 | BV16: 3115363 | BW16: 3146930 | BX16: 3256988.5 | BY16: {=XLOOKUP(C16,'PL TOTAL D0'!$A$3:$A$1991,'PL TOTAL D0'!$C$3:$C$1991,"")} -> 3334568.9
A17: BTG | B17: Aguinaldo Figueiredo de Freitas Junior | C17: 005662526 | D17: VcInvest | E17: GO | F17: Bruno Ribeiro | G17: =IFS($BS$4:$BS$1280<=250000,"David",$BS$4:$BS$1280<=800000,"Gabriel", $BS$4:$BS$1280>800000,"Marcus") -> David | H17: Inativo | I17: Sem Saldo | J17: =IF(Q17=0,"Não","Sim") -> Não | K17: 45450 | M17: EQT/ COADM | N17: 0.025 | O17: IBOVESPA | P17: 0.2 | S17: PF | T17: 817.848.051-49 | U17: 62981150222 | V17: afreitasjr@msn.com | W17: 28348 | X17: GO | Y17: =IFS(H:H="Encerrado","Encerrado",COUNTBLANK(AZ17:BK17)>0,"Ativo",SUM(AZ17:BK17)=0,"Inativo",SUM(AZ17:BK17)>0,"Ativo") -> Ativo | AA17: Arrojado | AB17: Qualificado | AD17: 45450 | AE17: 49075100015104 | AZ17: 104571.6 | BA17: 87237.69 | BB17: 91041.85 | BC17: 85312.49 | BD17: 88737.71 | BE17: 0 | BF17: 0.44 | BG17: 0.44 | BH17: 0.44 | BI17: 0.44 | BJ17: 0 | BK17: 0 | BL17: 0 | BM17: 0 | BN17: 0 | BO17: 0 | BP17: 0 | BQ17: 0 | BR17: 0 | BS17: 0 | BT17: 0 | BU17: 0 | BV17: 0 | BW17: 0 | BX17: 0 | BY17: {=XLOOKUP(C17,'PL TOTAL D0'!$A$3:$A$1991,'PL TOTAL D0'!$C$3:$C$1991,"")}
A18: BTG | B18: Ahmad Taha Comercio De Moveis LTDA | C18: 004368468 | D18: Miura | E18: SUL | F18: Lucas Zambrin | G18: =IFS($BS$4:$BS$1280<=250000,"David",$BS$4:$BS$1280<=800000,"Gabriel", $BS$4:$BS$1280>800000,"Marcus") -> Gabriel | H18: Inativo | I18: Monitoramento | J18: =IF(Q18=0,"Não","Sim") -> Sim | K18: 45582 | M18: CON | N18: 0.012 | O18: CDI | P18: 0.1 | Q18: Investimentos seguem a Sharia, Lei islamica. Investimentos Halal. ETF de Referência, ISWD. | R18: Cliente identificado como monitoramento por restrição devido a religião | S18: PJ | T18: 10.574.646/0001-36 | U18: 5511981868000 | V18: diretoria@todeschinisumare.com.br | W18: 39783 | X18: SP | Y18: =IFS(H:H="Encerrado","Encerrado",COUNTBLANK(AZ18:BK18)>0,"Ativo",SUM(AZ18:BK18)=0,"Inativo",SUM(AZ18:BK18)>0,"Ativo") -> Ativo | AA18: Moderado | AD18: 45582 | AE18: 49075100016097 | BD18: 483681.1 | BE18: 487885.79 | BF18: 489606.03 | BG18: 477789.7 | BH18: 477589.96 | BI18: 236577.61 | BJ18: 133028.09 | BK18: 136607.22 | BL18: 137215.12 | BM18: 138721.41 | BN18: 140304.7 | BO18: 142967.2 | BP18: 149312.2 | BQ18: 171247 | BR18: 384258.9 | BS18: 399197.96 | BT18: 504224.4 | BU18: 497980.1 | BV18: 507379 | BW18: 525045.4 | BX18: 519751.67 | BY18: {=XLOOKUP(C18,'PL TOTAL D0'!$A$3:$A$1991,'PL TOTAL D0'!$C$3:$C$1991,"")} -> 507506.12
A19: BTG | B19: Alan Mosele Tonin e/ou Laís Salgueiro Ribeiro | C19: 005312963 | D19: Bluemetrix | E19: GO | F19: Felipe Rios | G19: =IFS($BS$4:$BS$1280<=250000,"David",$BS$4:$BS$1280<=800000,"Gabriel", $BS$4:$BS$1280>800000,"Marcus") -> David | H19: Ativo | I19: ------ | J19: =IF(Q19=0,"Não","Sim") -> Sim | K19: 45357 | M19: CON/ GR | N19: 0.012 | O19: CDI | P19: 0.1 | Q19: Sem RV (15/05/2026) | S19: PF | T19: 026.921.410-08 | U19: 5561982721320 | V19: tonin.alan@gmail.com | W19: 32888 | X19: GO | Y19: =IFS(H:H="Encerrado","Encerrado",COUNTBLANK(AZ19:BK19)>0,"Ativo",SUM(AZ19:BK19)=0,"Inativo",SUM(AZ19:BK19)>0,"Ativo") -> Ativo | AB19: Qualificado | AD19: 45357 | AE19: 49075100013713 | AV19: 0 | AW19: 33983.76 | AX19: 98177.05 | AY19: 98794.34 | AZ19: 98998.72 | BA19: 100281 | BB19: 101463.62 | BC19: 101825.97 | BD19: 102496.99 | BE19: 102836.03 | BF19: 103617.96 | BG19: 104550.42 | BH19: 105483.12 | BI19: 106114.76 | BJ19: 105697.46 | BK19: 106672.82 | BL19: 107723.62 | BM19: 108914.2 | BN19: 109983.7 | BO19: 111106.01 | BP19: 112405.1 | BQ19: 113095 | BR19: 113976.9 | BS19: 92826.63 | BT19: 93627.6 | BU19: 94674.27 | BV19: 95779.62 | BW19: 180147 | BX19: 195646.56 | BY19: {=XLOOKUP(C19,'PL TOTAL D0'!$A$3:$A$1991,'PL TOTAL D0'!$C$3:$C$1991,"")} -> 202526.35
A20: BTG | B20: Alana Abreu Coimbra | C20: 005994117 | D20: Poupinvista | E20: DF | F20: Bruno Rodrigues | G20: =IFS($BS$4:$BS$1280<=250000,"David",$BS$4:$BS$1280<=800000,"Gabriel", $BS$4:$BS$1280>800000,"Marcus") -> Gabriel | H20: Ativo | I20: ------ | J20: =IF(Q20=0,"Não","Sim") -> Sim | K20: 45546 | M20: INC | N20: 0.012 | O20: ------ | P20: 0 | Q20: Aportes e vencimentos em D+0 (18/03/2026). | S20: PF | T20: 344.229.001-53 | U20: 61999715439 | V20: alanacoimbra@gmail.com | W20: 23857 | X20: DF | Y20: =IFS(H:H="Encerrado","Encerrado",COUNTBLANK(AZ20:BK20)>0,"Ativo",SUM(AZ20:BK20)=0,"Inativo",SUM(AZ20:BK20)>0,"Ativo") -> Ativo | AA20: Moderado | AD20: 45546 | AE20: 49075100015708 | BC20: 401814.81 | BD20: 405330.59 | BE20: 408226.49 | BF20: 411164.62 | BG20: 415332.78 | BH20: 419486.15 | BI20: 423535.35 | BJ20: 428483.6 | BK20: 432722.69 | BL20: 430542.53 | BM20: 421366.38 | BN20: 407408.5 | BO20: 396416.63 | BP20: 379280.6 | BQ20: 376706.4 | BR20: 376564.8 | BS20: 371963.16 | BT20: 354311.1 | BU20: 387271 | BV20: 383078.4 | BW20: 387174.8 | BX20: 400309.75 | BY20: {=XLOOKUP(C20,'PL TOTAL D0'!$A$3:$A$1991,'PL TOTAL D0'!$C$3:$C$1991,"")} -> 395290.08
A21: BTG | B21: Alberto Carlos de Aguiar Rodrigues | C21: 004376853 | D21: Bluemetrix | E21: DF | F21: Thiago Canabrava | G21: =IFS($BS$4:$BS$1280<=250000,"David",$BS$4:$BS$1280<=800000,"Gabriel", $BS$4:$BS$1280>800000,"Marcus") -> Gabriel | H21: Ativo | I21: ------ | J21: =IF(Q21=0,"Não","Sim") -> Sim | K21: 44980 | M21: MOD | N21: 0.015 | O21: ------ | P21: 0 | Q21: Não aumentar posição de RV. Sem CrPr e Aplicações com vencimento até 01/10/2027 (30/04/2026) Histórico | S21: PF | T21: 359.321.801-10 | U21: 5561999845191 | V21: alberto@ctecnet.com.br | W21: 24014 | X21: DF | Y21: =IFS(H:H="Encerrado","Encerrado",COUNTBLANK(AZ21:BK21)>0,"Ativo",SUM(AZ21:BK21)=0,"Inativo",SUM(AZ21:BK21)>0,"Ativo") -> Ativo | AB21: Qualificado | AD21: 44980 | AE21: 49075100005400 | AI21: 0 | AJ21: 172295.8 | AK21: 482402.02 | AL21: 483551.39 | AM21: 534786.71 | AN21: 567339.85 | AO21: 565993.39 | AP21: 562995.45 | AQ21: 566653.1 | AR21: 564056.01 | AS21: 587232.97 | AT21: 608841.45 | AU21: 599756.89 | AV21: 605484 | AW21: 622694.76 | AX21: 580164.47 | AY21: 559654.4 | AZ21: 572944.1 | BA21: 585837 | BB21: 602819.49 | BC21: 610879.04 | BD21: 529157.64 | BE21: 545335.75 | BF21: 463775.38 | BG21: 478567.58 | BH21: 493133.12 | BI21: 457393.45 | BJ21: 471644.77 | BK21: 481920.61 | BL21: 491582.81 | BM21: 506687.58 | BN21: 521512.6 | BO21: 536523.28 | BP21: 530847 | BQ21: 545331.1 | BR21: 560900.6 | BS21: 576247.53 | BT21: 586143.5 | BU21: 592275.8 | BV21: 702290.5 | BW21: 709674.2 | BX21: 726053.87 | BY21: {=XLOOKUP(C21,'PL TOTAL D0'!$A$3:$A$1991,'PL TOTAL D0'!$C$3:$C$1991,"")} -> 745514.65
A22: BTG | B22: Alberto de Oliveira Faleiro Neto | C22: 005142592 | D22: Bluemetrix | E22: DF | F22: Bruno Henrique | G22: =IFS($BS$4:$BS$1280<=250000,"David",$BS$4:$BS$1280<=800000,"Gabriel", $BS$4:$BS$1280>800000,"Marcus") -> David | H22: Inativo | I22: Monitoramento | J22: =IF(Q22=0,"Não","Sim") -> Sim | K22: 45279 | M22: MONT | N22: 0.003 | O22: ------ | P22: 0 | Q22: Carteira Monitoramento Especial para Fundos (SPMG FII criado pelo cliente) (04/10/2024) | S22: PF | T22: 898.277.406-87 | U22: 5531987441177 | V22: alberto@construtoraatrium.com.br | W22: 27458 | X22: MG | Y22: =IFS(H:H="Encerrado","Encerrado",COUNTBLANK(AZ22:BK22)>0,"Ativo",SUM(AZ22:BK22)=0,"Inativo",SUM(AZ22:BK22)>0,"Ativo") -> Ativo | AB22: Qualificado | AD22: 45279 | AE22: 49075100013268 | AS22: 0 | AT22: 0 | AU22: 0 | AV22: 551.13 | AW22: 551.26 | AX22: 551.37 | AY22: 551.48 | AZ22: 555.33 | BA22: 380631.3 | BB22: 376347.14 | BC22: 376252.33 | BD22: 2155715.1 | BE22: 2155437.8 | BF22: 2155439.1 | BG22: 2155440.5 | BH22: 2155441.8 | BI22: 2155443.1 | BJ22: 2155444.6 | BK22: 2155445 | BL22: 2155446.5 | BM22: 2155448.4 | BN22: 2155752 | BO22: 2155756.9 | BP22: 2155863 | BQ22: 0 | BR22: 18.73 | BS22: 385.91 | BT22: 386.03 | BU22: 0 | BV22: 0 | BW22: 0 | BX22: 0 | BY22: {=XLOOKUP(C22,'PL TOTAL D0'!$A$3:$A$1991,'PL TOTAL D0'!$C$3:$C$1991,"")}
A23: BTG | B23: Alberto Vilar Trindade | C23: 004480970 | D23: Bluemetrix | E23: DF | F23: Matheus Vilar | G23: =IFS($BS$4:$BS$1280<=250000,"David",$BS$4:$BS$1280<=800000,"Gabriel", $BS$4:$BS$1280>800000,"Marcus") -> David | H23: Encerrado | I23: ------ | J23: =IF(Q23=0,"Não","Sim") -> Não | K23: 45036 | L23: 45693 | M23: INC | N23: 0.012 | O23: ------ | P23: 0 | S23: PF | T23: 191.136.174-00 | X23: DF | Y23: =IFS(H:H="Encerrado","Encerrado",COUNTBLANK(AZ23:BK23)>0,"Ativo",SUM(AZ23:BK23)=0,"Inativo",SUM(AZ23:BK23)>0,"Ativo") -> Encerrado | AB23: Qualificado | AD23: 45036 | AE23: 49075100003963 | AL23: 20036.96 | AM23: 20245.2 | AN23: 20421.27 | AO23: 103098.95 | AP23: 104109.61 | AQ23: 104930.65 | AR23: 105845.33 | AS23: 106619.36 | AT23: 107450.42 | AU23: 128227.68 | AV23: 129200.16 | AW23: 130282.38 | AX23: 131317.71 | AY23: 132328.3 | AZ23: 9998.49 | BA23: 10088.41 | BB23: 412821.05 | BC23: 415876.47 | BD23: 0 | BE23: 0 | BF23: 0 | BG23: 0 | BH23: 0 | BI23: 0 | BJ23: 0 | BK23: 0 | BL23: 0 | BM23: 0 | BN23: 0 | BO23: 0 | BP23: 0 | BQ23: 0 | BR23: 0 | BS23: 0 | BT23: 0 | BU23: 0 | BV23: 0 | BW23: 0 | BX23: 0 | BY23: {=XLOOKUP(C23,'PL TOTAL D0'!$A$3:$A$1991,'PL TOTAL D0'!$C$3:$C$1991,"")}
A24: BTG | B24: Alessandra Andrade Vieira | C24: 005993550 | D24: Miura | E24: SUL | F24: Rodrigo Milanez | G24: =IFS($BS$4:$BS$1280<=250000,"David",$BS$4:$BS$1280<=800000,"Gabriel", $BS$4:$BS$1280>800000,"Marcus") -> David | H24: Encerrado | I24: ------ | J24: =IF(Q24=0,"Não","Sim") -> Não | K24: 45544 | L24: 45692 | M24: MONT | N24: 0 | O24: ------ | P24: 0 | R24: Alteração de carteira finalizada (17/12/2024) | S24: PF | T24: 864.270.919-72 | X24: PR | Y24: =IFS(H:H="Encerrado","Encerrado",COUNTBLANK(AZ24:BK24)>0,"Ativo",SUM(AZ24:BK24)=0,"Inativo",SUM(AZ24:BK24)>0,"Ativo") -> Encerrado | AA24: Moderado | AD24: 45544 | AE24: 49075100016151 | BC24: 0 | BD24: 0 | BE24: 0 | BF24: 540312.14 | BG24: 423046.77 | BH24: 0 | BI24: 0 | BJ24: 0 | BK24: 0 | BL24: 0 | BM24: 0 | BN24: 0 | BO24: 0 | BP24: 0 | BQ24: 0 | BR24: 0 | BS24: 0 | BT24: 0 | BU24: 0 | BV24: 0 | BW24: 0 | BX24: 0 | BY24: {=XLOOKUP(C24,'PL TOTAL D0'!$A$3:$A$1991,'PL TOTAL D0'!$C$3:$C$1991,"")}
A25: BTG | B25: Alessandra Charbel Janiques Rebouças | C25: 004713953 | D25: Bluemetrix | E25: DF | F25: Bluemetrix Asset | G25: =IFS($BS$4:$BS$1280<=250000,"David",$BS$4:$BS$1280<=800000,"Gabriel", $BS$4:$BS$1280>800000,"Marcus") -> Gabriel | H25: Ativo | I25: ------ | J25: =IF(Q25=0,"Não","Sim") -> Não | K25: 45106 | M25: INC | N25: 0.012 | O25: ------ | P25: 0 | S25: PF | T25: 539.413.301-87 | U25: 5561992140992 | V25: acjreboucas@gmail.com | W25: 26973 | X25: DF | Y25: =IFS(H:H="Encerrado","Encerrado",COUNTBLANK(AZ25:BK25)>0,"Ativo",SUM(AZ25:BK25)=0,"Inativo",SUM(AZ25:BK25)>0,"Ativo") -> Ativo | AB25: Qualificado | AD25: 45106 | AE25: 49075100006857 | AN25: 70008.87 | AO25: 70636.99 | AP25: 71354.76 | AQ25: 71920.45 | AR25: 72317.98 | AS25: 72834.21 | AT25: 73387.99 | AU25: 167576.59 | AV25: 191999.9 | AW25: 193638.73 | AX25: 205029.58 | AY25: 206188.7 | AZ25: 207731.3 | BA25: 209396.6 | BB25: 211112.7 | BC25: 212369.64 | BD25: 214181.97 | BE25: 215756.79 | BF25: 216568.79 | BG25: 218479.1 | BH25: 220076.86 | BI25: 303240.92 | BJ25: 306102.24 | BK25: 308447.91 | BL25: 311130.11 | BM25: 331553.92 | BN25: 334803.2 | BO25: 337750.82 | BP25: 341677 | BQ25: 344247 | BR25: 346599.5 | BS25: 350378.71 | BT25: 353240.9 | BU25: 355817.7 | BV25: 359291.8 | BW25: 363036.7 | BX25: 366457.95 | BY25: {=XLOOKUP(C25,'PL TOTAL D0'!$A$3:$A$1991,'PL TOTAL D0'!$C$3:$C$1991,"")} -> 369891.49
A26: BTG | B26: Alessandra Charbel Janiques Rebouças e/ou André Airton de Macedo Rebouças | C26: 005312576 | D26: Bluemetrix | E26: DF | F26: Bluemetrix Asset | G26: =IFS($BS$4:$BS$1280<=250000,"David",$BS$4:$BS$1280<=800000,"Gabriel", $BS$4:$BS$1280>800000,"Marcus") -> David | H26: Inativo | I26: Bloqueado | J26: =IF(Q26=0,"Não","Sim") -> Não | K26: 45356 | M26: CON | N26: 0.01 | O26: CDI | P26: 0.1 | S26: PF | T26: 539.413.301-87 | U26: 5561992140992 | V26: acjreboucas@gmail.com | W26: 26973 | X26: DF | Y26: =IFS(H:H="Encerrado","Encerrado",COUNTBLANK(AZ26:BK26)>0,"Ativo",SUM(AZ26:BK26)=0,"Inativo",SUM(AZ26:BK26)>0,"Ativo") -> Inativo | AB26: Qualificado | AD26: 45356 | AE26: 49075100013721 | AV26: 0 | AW26: 0 | AX26: 0 | AY26: 0 | AZ26: 0 | BA26: 0 | BB26: 0 | BC26: 0 | BD26: 0 | BE26: 0 | BF26: 0 | BG26: 0 | BH26: 0 | BI26: 0 | BJ26: 0 | BK26: 0 | BL26: 0 | BM26: 0 | BN26: 0 | BO26: 0 | BP26: 0 | BQ26: 0 | BR26: 0 | BS26: 0 | BT26: 0 | BU26: 0 | BV26: 0 | BW26: 0 | BX26: 0 | BY26: {=XLOOKUP(C26,'PL TOTAL D0'!$A$3:$A$1991,'PL TOTAL D0'!$C$3:$C$1991,"")}
A27: BTG | B27: Alessandra Daibert Couri | C27: 004872395 | D27: Voga | E27: DF | F27: Theo Ramos Moutinho | G27: =IFS($BS$4:$BS$1280<=250000,"David",$BS$4:$BS$1280<=800000,"Gabriel", $BS$4:$BS$1280>800000,"Marcus") -> David | H27: Encerrado | I27: ------ | J27: =IF(Q27=0,"Não","Sim") -> Não | K27: 45148 | L27: 45513 | M27: MOD/ PREV MOD | N27: 0.01 | O27: ------ | P27: 0 | S27: PF | T27: 030.345.906-95 | X27: DF | Y27: =IFS(H:H="Encerrado","Encerrado",COUNTBLANK(AZ27:BK27)>0,"Ativo",SUM(AZ27:BK27)=0,"Inativo",SUM(AZ27:BK27)>0,"Ativo") -> Encerrado | AB27: Qualificado | AD27: 45148 | AE27: 49075100012156 | AP27: 221510.59 | AQ27: 242583.64 | AR27: 243545.23 | AS27: 249632.92 | AT27: 267670.75 | AU27: 267143.19 | AV27: 272226.07 | AW27: 276789.02 | AX27: 291365.65 | AY27: 293881.1 | AZ27: 295514.8 | BA27: 0 | BB27: 0 | BC27: 0 | BD27: 0 | BE27: 0 | BF27: 0 | BG27: 0 | BH27: 0 | BI27: 0 | BJ27: 0 | BK27: 0 | BL27: 0 | BM27: 0 | BN27: 0 | BO27: 0 | BP27: 0 | BQ27: 0 | BR27: 0 | BS27: 0 | BT27: 0 | BU27: 0 | BV27: 0 | BW27: 0 | BX27: 0 | BY27: {=XLOOKUP(C27,'PL TOTAL D0'!$A$3:$A$1991,'PL TOTAL D0'!$C$3:$C$1991,"")}
A28: BTG | B28: Alessandra Nazare Crispim Goncalves | C28: 005749972 | D28: Bluemetrix | E28: DF | F28: Thiago Canabrava | G28: =IFS($BS$4:$BS$1280<=250000,"David",$BS$4:$BS$1280<=800000,"Gabriel", $BS$4:$BS$1280>800000,"Marcus") -> Gabriel | H28: Ativo | I28: ------ | J28: =IF(Q28=0,"Não","Sim") -> Não | K28: 45488 | M28: INC | N28: 0.012 | O28: ------ | P28: 0 | S28: PF | T28: 712.174.601-87 | U28: 61998010160 | V28: alessacrispim@gmail.com | W28: 29188 | X28: DF | Y28: =IFS(H:H="Encerrado","Encerrado",COUNTBLANK(AZ28:BK28)>0,"Ativo",SUM(AZ28:BK28)=0,"Inativo",SUM(AZ28:BK28)>0,"Ativo") -> Ativo | AA28: Conservador | AB28: Qualificado | AD28: 45488 | AE28: 49075100015473 | BA28: 80196.25 | BB28: 470775.27 | BC28: 483335.63 | BD28: 487785.93 | BE28: 491549.24 | BF28: 495553.15 | BG28: 500406.42 | BH28: 505027.51 | BI28: 510415.32 | BJ28: 515491.31 | BK28: 520845.98 | BL28: 525177.79 | BM28: 530486.51 | BN28: 533248.5 | BO28: 538162.47 | BP28: 544608.5 | BQ28: 549288.8 | BR28: 538424.5 | BS28: 543859.22 | BT28: 544891.8 | BU28: 546435.6 | BV28: 538739.1 | BW28: 544751.1 | BX28: 549764.32 | BY28: {=XLOOKUP(C28,'PL TOTAL D0'!$A$3:$A$1991,'PL TOTAL D0'!$C$3:$C$1991,"")} -> 550274.29
A29: BTG | B29: Alessandra Padilha Valle Kanitz | C29: 004946542 | D29: Bluemetrix | E29: DF | F29: Gustavo Amorim | G29: =IFS($BS$4:$BS$1280<=250000,"David",$BS$4:$BS$1280<=800000,"Gabriel", $BS$4:$BS$1280>800000,"Marcus") -> David | H29: Ativo | I29: ------ | J29: =IF(Q29=0,"Não","Sim") -> Sim | K29: 45160 | M29: INC | N29: 0.012 | O29: ------ | P29: 0 | Q29: 30k D+0 (29/09/2025) | S29: PF | T29: 610.888.701-04 | U29: 61992757864 | V29: alepvk@gmail.com | W29: 26873 | X29: DF | Y29: =IFS(H:H="Encerrado","Encerrado",COUNTBLANK(AZ29:BK29)>0,"Ativo",SUM(AZ29:BK29)=0,"Inativo",SUM(AZ29:BK29)>0,"Ativo") -> Ativo | AB29: Qualificado | AD29: 45160 | AE29: 49075100008019 | AP29: 601175.9 | AQ29: 606237.94 | AR29: 611489.99 | AS29: 615841.54 | AT29: 619579.86 | AU29: 625184.81 | AV29: 629881.63 | AW29: 633953.26 | AX29: 638440.22 | AY29: 643538.6 | AZ29: 648288.5 | BA29: 653705.9 | BB29: 654754.17 | BC29: 659134.65 | BD29: 665198.12 | BE29: 670243.63 | BF29: 675415.97 | BG29: 681856.15 | BH29: 688297.79 | BI29: 180510.23 | BJ29: 182238.25 | BK29: 184182 | BL29: 185869.95 | BM29: 188064.14 | BN29: 189376.3 | BO29: 191357.53 | BP29: 162856.3 | BQ29: 164474 | BR29: 160669.3 | BS29: 162463.56 | BT29: 128469.9 | BU29: 130178.5 | BV29: 131884.7 | BW29: 126506.8 | BX29: 122955.71 | BY29: {=XLOOKUP(C29,'PL TOTAL D0'!$A$3:$A$1991,'PL TOTAL D0'!$C$3:$C$1991,"")} -> 114440.98
A30: BTG | B30: Alessandra Sado | C30: 020016028 | D30: VcInvest | E30: GO | F30: Bruno Ribeiro | G30: Gabriel | H30: Ativo | I30: ------ | J30: =IF(Q30=0,"Não","Sim") -> Não | K30: 46094 | M30: INC | N30: 0.012 | O30: ------ | P30: 0 | S30: PF | T30: 788.043.611-15 | U30: 62 98139-0612 | V30: alessandrasado@gmail.com | W30: 27672 | X30: GO | Y30: =IFS(H:H="Encerrado","Encerrado",COUNTBLANK(AZ30:BK30)>0,"Ativo",SUM(AZ30:BK30)=0,"Inativo",SUM(AZ30:BK30)>0,"Ativo") -> Ativo | AA30: Moderado | AD30: 46203 | BU30: 688247 | BV30: 677760.6 | BW30: 1619387 | BX30: 1925112.2 | BY30: {=XLOOKUP(C30,'PL TOTAL D0'!$A$3:$A$1991,'PL TOTAL D0'!$C$3:$C$1991,"")} -> 1950686.6
A31: BTG | B31: Alessandro Alcantara Correira | C31: 008032597 | D31: Bluemetrix | E31: DF | F31: Thiago Canabrava | G31: =IFS($BS$4:$BS$1280<=250000,"David",$BS$4:$BS$1280<=800000,"Gabriel", $BS$4:$BS$1280>800000,"Marcus") -> David | H31: Ativo | I31: ------ | J31: =IF(Q31=0,"Não","Sim") -> Sim | K31: 45565 | M31: INC | N31: 0.012 | O31: ------ | P31: 0 | Q31: 40K até D+1 (17/10/2024) | S31: PF | T31: 092.878.271-92 | U31: 61998002436 | V31: alessandrocorreira@gmail.com | W31: 38545 | X31: DF | Y31: =IFS(H:H="Encerrado","Encerrado",COUNTBLANK(AZ31:BK31)>0,"Ativo",SUM(AZ31:BK31)=0,"Inativo",SUM(AZ31:BK31)>0,"Ativo") -> Ativo | AA31: Conservador | AD31: 45565 | AE31: 49075100016070 | BC31: 0 | BD31: 144963.23 | BE31: 146156.63 | BF31: 147289.33 | BG31: 148666.98 | BH31: 141273.71 | BI31: 143140.31 | BJ31: 118564.79 | BK31: 117015.29 | BL31: 118039.22 | BM31: 110912.16 | BN31: 112195.6 | BO31: 112891.31 | BP31: 113730.6 | BQ31: 107003.4 | BR31: 108003.4 | BS31: 109198.28 | BT31: 106322 | BU31: 107565.8 | BV31: 105829.7 | BW31: 106818.8 | BX31: 107802.44 | BY31: {=XLOOKUP(C31,'PL TOTAL D0'!$A$3:$A$1991,'PL TOTAL D0'!$C$3:$C$1991,"")} -> 109077.68
A32: BTG | B32: Alessandro Alcantara Correira | C32: 008569831 | D32: Bluemetrix | E32: DF | F32: Thiago Canabrava | G32: =IFS($BS$4:$BS$1280<=250000,"David",$BS$4:$BS$1280<=800000,"Gabriel", $BS$4:$BS$1280>800000,"Marcus") -> David | H32: Inativo | I32: Monitoramento | J32: =IF(Q32=0,"Não","Sim") -> Não | K32: 45743 | M32: MONT | N32: 0.005 | O32: ------ | P32: 0 | S32: PF | T32: 092.878.271-92 | U32: 61998002436 | V32: alessandrocorreira@gmail.com | W32: 38545 | X32: DF | Y32: =IFS(H:H="Encerrado","Encerrado",COUNTBLANK(AZ32:BK32)>0,"Ativo",SUM(AZ32:BK32)=0,"Inativo",SUM(AZ32:BK32)>0,"Ativo") -> Ativo | AA32: Conservador | AD32: 45757 | AE32: 49075100018723 | BI32: 0 | BJ32: 20829.9 | BK32: 21006.05 | BL32: 9091.95 | BM32: 9198.3 | BN32: 9303.51 | BO32: 1270.16 | BP32: 1286.84 | BQ32: 1287.07 | BR32: 0.53 | BS32: 0.53 | BT32: 0.53 | BU32: 0.53 | BV32: 2054 | BW32: 0 | BX32: 0.02 | BY32: {=XLOOKUP(C32,'PL TOTAL D0'!$A$3:$A$1991,'PL TOTAL D0'!$C$3:$C$1991,"")}
A33: BTG | B33: Alessandro Luis Almeida Bacelar Gama | C33: 004252768 | D33: Altum | E33: DF | F33: João Victor de Moura Beze | G33: =IFS($BS$4:$BS$1280<=250000,"David",$BS$4:$BS$1280<=800000,"Gabriel", $BS$4:$BS$1280>800000,"Marcus") -> David | H33: Encerrado | I33: ------ | J33: =IF(Q33=0,"Não","Sim") -> Não | K33: 44958 | L33: 45775 | M33: INC | N33: 0.012 | O33: ------ | P33: 0 | S33: PF | T33: 030.523.481-16 | X33: DF | Y33: =IFS(H:H="Encerrado","Encerrado",COUNTBLANK(AZ33:BK33)>0,"Ativo",SUM(AZ33:BK33)=0,"Inativo",SUM(AZ33:BK33)>0,"Ativo") -> Encerrado | AB33: Qualificado | AD33: 44958 | AE33: 49075100010242 | AK33: 53545.8 | AL33: 54182.77 | AM33: 288087.22 | AN33: 344984.05 | AO33: 347862.28 | AP33: 400633.57 | AQ33: 262688.84 | AR33: 405398.15 | AS33: 408413 | AT33: 411553.44 | AU33: 415212.78 | AV33: 418571.1 | AW33: 238572.2 | AX33: 239496.64 | AY33: 241378.1 | AZ33: 242844.8 | BA33: 244871.4 | BB33: 246300.96 | BC33: 247154.56 | BD33: 249300.04 | BE33: 251095.83 | BF33: 252850.55 | BG33: 0 | BH33: 0 | BI33: 0 | BJ33: 0 | BK33: 0 | BL33: 0 | BM33: 0 | BN33: 0 | BO33: 0 | BP33: 0 | BQ33: 0 | BR33: 0 | BS33: 0 | BT33: 0 | BU33: 0 | BV33: 0 | BW33: 0 | BX33: 0 | BY33: {=XLOOKUP(C33,'PL TOTAL D0'!$A$3:$A$1991,'PL TOTAL D0'!$C$3:$C$1991,"")}
A34: BTG | B34: Alessandro Pasqualinotti | C34: 022511372 | D34: Miura | E34: SUL | F34: Lucas Zambrin | G34: =IFS($BS$4:$BS$1280<=250000,"David",$BS$4:$BS$1280<=800000,"Gabriel", $BS$4:$BS$1280>800000,"Marcus") -> David | H34: Ativo | I34: ------ | J34: =IF(Q34=0,"Não","Sim") -> Não | K34: 46083 | M34: MOD | N34: 0.015 | O34: CDI | P34: 0.1 | S34: PF | T34: 865.989.029-91 | U34: 43 99149-0648 | V34: comercial@jplembalagens.com.br | W34: 26604 | X34: PR | Y34: =IFS(H:H="Encerrado","Encerrado",COUNTBLANK(AZ34:BK34)>0,"Ativo",SUM(AZ34:BK34)=0,"Inativo",SUM(AZ34:BK34)>0,"Ativo") -> Ativo | AA34: Moderado | AD34: 46203 | BU34: 0 | BV34: 0 | BW34: 489347.2 | BX34: 495711.5 | BY34: {=XLOOKUP(C34,'PL TOTAL D0'!$A$3:$A$1991,'PL TOTAL D0'!$C$3:$C$1991,"")} -> 534945.84
A35: BTG | B35: Alexandre Cardoso Barreto Santana | C35: 005823200 | D35: Investeseg | E35: BA | F35: Murilo Silva | G35: =IFS($BS$4:$BS$1280<=250000,"David",$BS$4:$BS$1280<=800000,"Gabriel", $BS$4:$BS$1280>800000,"Marcus") -> David | H35: Ativo | I35: ------ | J35: =IF(Q35=0,"Não","Sim") -> Não | K35: 46212 | M35: MOD | N35: 0.015 | O35: CDI | P35: 0.1 | S35: PF | T35: 784.038.805-10 | U35: 71 98884-7559 | V35: alexandre.ucsal@hotmail.com | W35: 29918 | X35: BA | Y35: =IFS(H:H="Encerrado","Encerrado",COUNTBLANK(AZ35:BK35)>0,"Ativo",SUM(AZ35:BK35)=0,"Inativo",SUM(AZ35:BK35)>0,"Ativo") -> Ativo | AA35: Moderado | BX35: 0 | BY35: {=XLOOKUP(C35,'PL TOTAL D0'!$A$3:$A$1991,'PL TOTAL D0'!$C$3:$C$1991,"")} -> 150923.26
A36: BTG | B36: Alexandre De Paula Trindade | C36: 026366781 | D36: Miura | E36: SUL | F36: Lucas Zambrin | G36: =IFS($BS$4:$BS$1280<=250000,"David",$BS$4:$BS$1280<=800000,"Gabriel", $BS$4:$BS$1280>800000,"Marcus") -> David | H36: Ativo | I36: ------ | J36: =IF(Q36=0,"Não","Sim") -> Não | K36: 46216 | M36: MOD | N36: 0.015 | O36: CDI | P36: 0.1 | S36: PF | T36: 551.349.399-34 | U36: 43 99614-0505 | V36: alexpt.uniware@gmail.com | W36: 23797 | X36: PR | Y36: =IFS(H:H="Encerrado","Encerrado",COUNTBLANK(AZ36:BK36)>0,"Ativo",SUM(AZ36:BK36)=0,"Inativo",SUM(AZ36:BK36)>0,"Ativo") -> Ativo | AA36: Arrojado | BX36: 0 | BY36: {=XLOOKUP(C36,'PL TOTAL D0'!$A$3:$A$1991,'PL TOTAL D0'!$C$3:$C$1991,"")} -> 452141.01
A37: BTG | B37: Alexandre Lopes Figueiredo | C37: 004520100 | D37: Miura | E37: SUL | F37: Rodrigo Milanez | G37: =IFS($BS$4:$BS$1280<=250000,"David",$BS$4:$BS$1280<=800000,"Gabriel", $BS$4:$BS$1280>800000,"Marcus") -> David | H37: Ativo | I37: ------ | J37: =IF(Q37=0,"Não","Sim") -> Não | K37: 45982 | M37: INC | N37: 0.012 | O37: ------ | P37: 0 | R37: STVM de entrada da Guide finalizada (10/09/2023) | S37: PF | T37: 841.104.149-20 | U37: 43 98828-1735 | V37: alfgf22@gmail.com | W37: 25802 | X37: PR | Y37: =IFS(H:H="Encerrado","Encerrado",COUNTBLANK(AZ37:BK37)>0,"Ativo",SUM(AZ37:BK37)=0,"Inativo",SUM(AZ37:BK37)>0,"Ativo") -> Ativo | AA37: Moderado | AB37: Qualificado | AD37: 45166 | AE37: 49075100011052 | AL37: 0 | AM37: 0 | AN37: 0 | AO37: 0 | AP37: 0 | AQ37: 238854.55 | AR37: 237988.82 | AS37: 243644.48 | AT37: 248581.27 | AU37: 243901.96 | AV37: 22702.09 | AW37: 22583.51 | AX37: 22731.6 | AY37: 22870.18 | AZ37: 23007.81 | BA37: 23185.59 | BB37: 23352.68 | BC37: 23514.39 | BD37: 0 | BE37: 0 | BF37: 0 | BG37: 0 | BH37: 0 | BI37: 0 | BJ37: 0 | BK37: 0 | BL37: 0 | BM37: 0 | BN37: 0 | BO37: 0 | BP37: 0 | BQ37: 113570.4 | BR37: 114815.4 | BS37: 115959.86 | BT37: 116980.1 | BU37: 118349.3 | BV37: 119638.5 | BW37: 120916.8 | BX37: 121652.51 | BY37: {=XLOOKUP(C37,'PL TOTAL D0'!$A$3:$A$1991,'PL TOTAL D0'!$C$3:$C$1991,"")} -> 122978.6
A38: BTG | B38: Alexandre Ramos Vieira | C38: 005558076 | D38: Altum | E38: DF | F38: Paula Lemos | G38: =IFS($BS$4:$BS$1280<=250000,"David",$BS$4:$BS$1280<=800000,"Gabriel", $BS$4:$BS$1280>800000,"Marcus") -> David | H38: Inativo | I38: Sem Saldo | J38: =IF(Q38=0,"Não","Sim") -> Não | K38: 45426 | M38: INC | N38: 0.012 | O38: ------ | P38: 0 | S38: PF | T38: 120.779.681-68 | U38: 5561995360707 | V38: alexvieira22071@gmail.com | W38: 20606 | X38: DF | Y38: =IFS(H:H="Encerrado","Encerrado",COUNTBLANK(AZ38:BK38)>0,"Ativo",SUM(AZ38:BK38)=0,"Inativo",SUM(AZ38:BK38)>0,"Ativo") -> Ativo | AA38: Conservador | AB38: Qualificado | AD38: 45426 | AE38: 49075100014401 | AY38: 100500.8 | AZ38: 101325.3 | BA38: 102220.7 | BB38: 103033.35 | BC38: 103776.92 | BD38: 104644.94 | BE38: 105385.27 | BF38: 105970.95 | BG38: 106908.07 | BH38: 107768.52 | BI38: 104640.99 | BJ38: 105788.83 | BK38: 0 | BL38: 46.08 | BM38: 46.08 | BN38: 46.08 | BO38: 46.08 | BP38: 46.08 | BQ38: 46.08 | BR38: 46.08 | BS38: 46.08 | BT38: 46.08 | BU38: 46.08 | BV38: 46.08 | BW38: 46.08 | BX38: 46.08 | BY38: {=XLOOKUP(C38,'PL TOTAL D0'!$A$3:$A$1991,'PL TOTAL D0'!$C$3:$C$1991,"")}
A39: BTG | B39: Alexandre Strauch Pereira Coutinho | C39: 005022526 | D39: Bluemetrix | E39: DF | F39: Matheus Vilar | G39: =IFS($BS$4:$BS$1280<=250000,"David",$BS$4:$BS$1280<=800000,"Gabriel", $BS$4:$BS$1280>800000,"Marcus") -> David | H39: Encerrado | I39: ------ | J39: =IF(Q39=0,"Não","Sim") -> Não | K39: 45201 | L39: 45414 | M39: INC | N39: 0.01 | O39: ------ | P39: 0 | R39: Cliente vai resgatar sozinho/ Troca de Assessoria de Thiago Canbrava para Matheus Vilar | S39: PF | T39: 028.189.781-65 | X39: DF | Y39: =IFS(H:H="Encerrado","Encerrado",COUNTBLANK(AZ39:BK39)>0,"Ativo",SUM(AZ39:BK39)=0,"Inativo",SUM(AZ39:BK39)>0,"Ativo") -> Encerrado | AB39: Não Qualificado | AD39: 45201 | AE39: 49075100011079 | AQ39: 0 | AR39: 56301.66 | AS39: 56710.28 | AT39: 57141.5 | AU39: 57124.59 | AV39: 57677.35 | AW39: 58076.04 | AX39: 0 | AY39: 0 | AZ39: 1.7 | BA39: 1.7 | BB39: 1.7 | BC39: 1.7 | BD39: 1.7 | BE39: 1.7 | BF39: 1.7 | BG39: 1.7 | BH39: 1.7 | BI39: 1.7 | BJ39: 0 | BK39: 0 | BL39: 0 | BM39: 0 | BN39: 0 | BO39: 0 | BP39: 0 | BQ39: 0 | BR39: 0 | BS39: 0 | BT39: 0 | BU39: 0 | BV39: 0 | BW39: 0 | BX39: 0 | BY39: {=XLOOKUP(C39,'PL TOTAL D0'!$A$3:$A$1991,'PL TOTAL D0'!$C$3:$C$1991,"")}
A40: BTG | B40: Alexandre Strauch Pereira Coutinho | C40: 005019925 | D40: Bluemetrix | E40: DF | F40: Matheus Vilar | G40: =IFS($BS$4:$BS$1280<=250000,"David",$BS$4:$BS$1280<=800000,"Gabriel", $BS$4:$BS$1280>800000,"Marcus") -> David | H40: Encerrado | I40: ------ | J40: =IF(Q40=0,"Não","Sim") -> Não | K40: 45196 | L40: 45414 | M40: EQT | N40: 0.02 | O40: IBOVESPA | P40: 0.2 | R40: Aguardando resposta do FA / Troca de Assessoria de Thiago Canbrava para Matheus Vilar | S40: PF | T40: 028.189.781-65 | U40: 5561981567737 | V40: alexandre.strauch@hotmail.com | W40: 32257 | X40: DF | Y40: =IFS(H:H="Encerrado","Encerrado",COUNTBLANK(AZ40:BK40)>0,"Ativo",SUM(AZ40:BK40)=0,"Inativo",SUM(AZ40:BK40)>0,"Ativo") -> Encerrado | AB40: Não Qualificado | AD40: 45196 | AE40: 49075100011060 | AQ40: 0 | AR40: 0 | AS40: 0 | AT40: 0 | AU40: 0 | AV40: 1.06 | AW40: 1.06 | AX40: 0 | AY40: 0 | AZ40: 0 | BA40: 0 | BB40: 0 | BC40: 0 | BD40: 0 | BE40: 0 | BF40: 0 | BG40: 0 | BH40: 0 | BI40: 0 | BJ40: 1.7 | BK40: 1.7 | BL40: 1.7 | BM40: 1.7 | BN40: 1.7 | BO40: 1.7 | BP40: 1.7 | BQ40: 1.7 | BR40: 1.7 | BS40: 1.7 | BT40: 1.7 | BU40: 1.7 | BV40: 1.7 | BW40: 1.7 | BX40: 1.7 | BY40: {=XLOOKUP(C40,'PL TOTAL D0'!$A$3:$A$1991,'PL TOTAL D0'!$C$3:$C$1991,"")}
...

Sheet XP
A1: Backoffice | G1: Mesa de Operação | H1: Backoffice/ Mesa | J1: Backoffice | Q1: Mesa de Operação | R1: Backoffice | S1: Anbima | AF1: Financeiro | AG1: Financeiro | AH1: Financeiro | AI1: Financeiro | AJ1: Financeiro | AK1: Financeiro | AL1: Financeiro | AM1: Financeiro | AN1: Financeiro | AO1: Financeiro | AP1: Financeiro | AQ1: Financeiro | AR1: Financeiro | AS1: Financeiro | AT1: Financeiro | AU1: Financeiro | AV1: Financeiro | AW1: Financeiro | AX1: Financeiro | AY1: Financeiro | AZ1: Financeiro
A2: Corretora | B2: Cliente | C2: Conta | D2: Escritório | E2: UF | F2: Assessor | G2: Operador | H2: Status | I2: Situação | J2: Exceção | K2: Início da Gestão | L2: Data distrato | M2: Carteira | N2: Taxa de Gestão | O2: Benchmark TX. Perf. | P2: TX. Perf. | Q2: Observações | R2: Observações Backoffice | S2: PF/ PJ | T2: CPF/CNPJ | U2: Telefone | V2: E-mail | W2: Aniversário | X2: UF cliente | Y2: Status Anbima | Z2: Perfil de risco da carteira | AA2: Perfil de risco do investidor | AB2: Classificação do Investidor | AC2: Grupo Econômico (Região) | AD2: Data Primeiro Aporte | AE2: Código Anbima | AF2: 29/11/2024 | AG2: 31/12/2024 | AH2: 31/01/2025 | AI2: 28/02/2025 | AJ2: 31/03/2025 | AK2: 30/04/2025 | AL2: 30/05/2025 | AM2: 30/06/2025 | AN2: 31/07/2025 | AO2: 31/08/2025 | AP2: 30/09/2025 | AQ2: 31/10/2025 | AR2: 30/11/2025 | AS2: 31/12/2025 | AT2: 31/01/2026 | AU2: 28/02/2026 | AV2: 31/03/2026 | AW2: 30/04/2026 | AX2: 31/05/2026 | AY2: 30/06/2026 | AZ2: Julho (D-1)
A3: XP | B3: Adilton Jose Nunes | C3: 3757672 | D3: VcInvest | E3: GO | F3: Bruno Ribeiro | G3: =IFS($AZ$3:$AZ$993<=250000,"David",$AZ$3:$AZ$993<=800000,"Gabriel", $AZ$3:$AZ$993>800000,"Marcus") -> Gabriel | H3: Ativo | I3: ------ | J3: =IF(Q3=0,"Não","Sim") -> Não | K3: 45840 | M3: INC | N3: 0.012 | O3: ------ | P3: 0 | S3: PF | T3: 291.691.191-04 | U3: (62) - 996986126 | V3: adiltonj2010@hotmail.com | W3: 23179 | X3: GO | Y3: =IFS(H:H="Encerrado","Encerrado",COUNTBLANK(AF3:AN3)>0,"Ativo",SUM(AF3:AN3)=0,"Inativo",SUM(AF3:AN3)>0,"Ativo") -> Ativo | AA3: Arrojado | AD3: 45840 | AE3: 49075100019258 | AN3: 144331.95 | AO3: 142905.94 | AP3: 144341.88 | AQ3: 146055.67 | AR3: 147170.09 | AS3: 148443.65 | AT3: 260339.53 | AU3: 262739.38 | AV3: 265297.43 | AW3: 268181.36 | AX3: 270597.74 | AY3: 273498.9 | AZ3: {=XLOOKUP(C3,'PL TOTAL D0'!K:K,'PL TOTAL D0'!L:L,"")} -> 276308.66
A4: XP | B4: Adilton Jose Nunes | C4: 18408485 | D4: VcInvest | E4: GO | F4: Bruno Ribeiro | G4: =IFS($AZ$3:$AZ$993<=250000,"David",$AZ$3:$AZ$993<=800000,"Gabriel", $AZ$3:$AZ$993>800000,"Marcus") -> David | H4: Ativo | I4: ------ | J4: =IF(Q4=0,"Não","Sim") -> Não | K4: 45866 | M4: EQT | N4: 0.025 | O4: IBOVESPA | P4: 0.2 | S4: PF | T4: 291.691.191-04 | U4: (62) - 996986126 | V4: adiltonj2010@hotmail.com | W4: 23179 | X4: GO | Y4: =IFS(H:H="Encerrado","Encerrado",COUNTBLANK(AF4:AN4)>0,"Ativo",SUM(AF4:AN4)=0,"Inativo",SUM(AF4:AN4)>0,"Ativo") -> Ativo | AA4: Arrojado | AD4: 45881 | AE4: 49075100019355 | AN4: 100 | AO4: 53659.64 | AP4: 62438.8 | AQ4: 63293.59 | AR4: 65878.76 | AS4: 67022.39 | AT4: 73515.96 | AU4: 76142 | AV4: 75570.13 | AW4: 75868.5 | AX4: 71064.05 | AY4: 73223.4 | AZ4: {=XLOOKUP(C4,'PL TOTAL D0'!K:K,'PL TOTAL D0'!L:L,"")} -> 72629.59
A5: XP | B5: Adriana Princhak Teixeira Pinto | C5: 19584661 | D5: Poupinvista | E5: DF | F5: Bruno Rodrigues | G5: =IFS($AZ$3:$AZ$993<=250000,"David",$AZ$3:$AZ$993<=800000,"Gabriel", $AZ$3:$AZ$993>800000,"Marcus") -> David | H5: Ativo | I5: ------ | J5: =IF(Q5=0,"Não","Sim") -> Sim | K5: 46169 | M5: INC | N5: 0.012 | O5: ------ | P5: 0 | Q5: 40k PGBL (27/05/2026). | S5: PF | T5: 016.900.761-86 | U5: 61 98121-7104 | V5: adrianaprinchak@gmail.com | W5: 31348 | X5: DF | Y5: =IFS(H:H="Encerrado","Encerrado",COUNTBLANK(AF5:AN5)>0,"Ativo",SUM(AF5:AN5)=0,"Inativo",SUM(AF5:AN5)>0,"Ativo") -> Ativo | AA5: Moderado | AX5: 0 | AY5: 0 | AZ5: {=XLOOKUP(C5,'PL TOTAL D0'!K:K,'PL TOTAL D0'!L:L,"")} -> 0
A6: XP | B6: A & R Sinalização E Comunicação Visual Eireli | C6: 3227135 | D6: MI Smart | E6: DF | F6: Mariana Rocha | G6: =IFS($AZ$3:$AZ$993<=250000,"David",$AZ$3:$AZ$993<=800000,"Gabriel", $AZ$3:$AZ$993>800000,"Marcus") -> Gabriel | H6: Ativo | I6: ------ | J6: =IF(Q6=0,"Não","Sim") -> Não | K6: 45716 | M6: INC | N6: 0.012 | O6: ------ | P6: 0 | S6: PJ | T6: 10.909.603/0001-64 | U6: (61) - 33997458 | V6: renato@lasersign.com.br | W6: PJ | X6: DF | Y6: =IFS(H:H="Encerrado","Encerrado",COUNTBLANK(AF6:AN6)>0,"Ativo",SUM(AF6:AN6)=0,"Inativo",SUM(AF6:AN6)>0,"Ativo") -> Ativo | AA6: Conservador | AD6: 45716 | AE6: 49075100017883 | AI6: 842201.12 | AJ6: 820350.4 | AK6: 832914.4 | AL6: 840525.35 | AM6: 840554.62 | AN6: 731771.97 | AO6: 678081.35 | AP6: 650393.33 | AQ6: 656400.56 | AR6: 628389.07 | AS6: 631304.17 | AT6: 631089.14 | AU6: 632622.02 | AV6: 499988.42 | AW6: 467612.11 | AX6: 378002.9 | AY6: 303308.58 | AZ6: {=XLOOKUP(C6,'PL TOTAL D0'!K:K,'PL TOTAL D0'!L:L,"")} -> 334477.35
A7: XP | B7: Afrisio de Souza Vieira Lima Filho | C7: 3345620 | D7: Bluemetrix | E7: DF | F7: Thiago Canabrava | G7: =IFS($AZ$3:$AZ$993<=250000,"David",$AZ$3:$AZ$993<=800000,"Gabriel", $AZ$3:$AZ$993>800000,"Marcus") -> David | H7: Ativo | I7: ------ | J7: =IF(Q7=0,"Não","Sim") -> Não | K7: 45693 | M7: INC | N7: 0.01 | O7: ------ | P7: 0 | S7: PF | T7: 152.774.535-04 | U7: (61) - 999811812 | V7: afrisio.lima@gmail.com | W7: 22296 | X7: DF | Y7: =IFS(H:H="Encerrado","Encerrado",COUNTBLANK(AF7:AN7)>0,"Ativo",SUM(AF7:AN7)=0,"Inativo",SUM(AF7:AN7)>0,"Ativo") -> Ativo | AA7: Moderado | AD7: 45693 | AE7: 49075100017786 | AH7: 0 | AI7: 220942.88 | AJ7: 222804.23 | AK7: 222781.11 | AL7: 223578.53 | AM7: 225342 | AN7: 228033.33 | AO7: 229031.43 | AP7: 231975.33 | AQ7: 233960.2 | AR7: 234330.74 | AS7: 235902.95 | AT7: 234990.11 | AU7: 232989.07 | AV7: 233605.17 | AW7: 226088.08 | AX7: 224469.08 | AY7: 220949.48 | AZ7: {=XLOOKUP(C7,'PL TOTAL D0'!K:K,'PL TOTAL D0'!L:L,"")} -> 217332.28
A8: XP | B8: Ailton Cabral Moraes | C8: 6853541 | D8: MI Smart | E8: DF | F8: Mariana Rocha | G8: =IFS($AZ$3:$AZ$993<=250000,"David",$AZ$3:$AZ$993<=800000,"Gabriel", $AZ$3:$AZ$993>800000,"Marcus") -> Marcus | H8: Ativo | I8: ------ | J8: =IF(Q8=0,"Não","Sim") -> Sim | K8: 45706 | M8: INC | N8: 0.012 | O8: ------ | P8: 0 | Q8: 200K D+0 (28/03/2025) | S8: PF | T8: 797.611.191-49 | U8: (61) - 999803078 | V8: ailtoncabral.moraes@gmail.com | W8: 28224 | X8: DF | Y8: =IFS(H:H="Encerrado","Encerrado",COUNTBLANK(AF8:AN8)>0,"Ativo",SUM(AF8:AN8)=0,"Inativo",SUM(AF8:AN8)>0,"Ativo") -> Ativo | AA8: Conservador | AD8: 45706 | AE8: 49075100018049 | AI8: 1308459.3 | AJ8: 1310131.3 | AK8: 1257958.1 | AL8: 1244862 | AM8: 1250582.3 | AN8: 1194830.3 | AO8: 1215000.1 | AP8: 1247894.5 | AQ8: 1265149.5 | AR8: 1271935.1 | AS8: 1099430.7 | AT8: 1112984.4 | AU8: 1260354.6 | AV8: 1127073.8 | AW8: 1152364.5 | AX8: 1062329.7 | AY8: 1030096.6 | AZ8: {=XLOOKUP(C8,'PL TOTAL D0'!K:K,'PL TOTAL D0'!L:L,"")} -> 1027647.2
A9: XP | B9: Alden Mangueira De Oliveira | C9: 15466228 | D9: MI Smart | E9: DF | F9: Mariana Rocha | G9: =IFS($AZ$3:$AZ$993<=250000,"David",$AZ$3:$AZ$993<=800000,"Gabriel", $AZ$3:$AZ$993>800000,"Marcus") -> Marcus | H9: Encerrado | I9: ------ | J9: =IF(Q9=0,"Não","Sim") -> Sim | K9: 45706 | L9: 45937 | M9: INC | N9: 0.012 | O9: ------ | P9: 0 | Q9: 100K D+0 (28/03/2025) | S9: PF | T9: 843.999.297-15 | U9: (61) - 992745523 | V9: alden.mangueira@gmail.com | W9: 24514 | X9: DF | Y9: =IFS(H:H="Encerrado","Encerrado",COUNTBLANK(AF9:AN9)>0,"Ativo",SUM(AF9:AN9)=0,"Inativo",SUM(AF9:AN9)>0,"Ativo") -> Encerrado | AA9: Conservador | AD9: 45706 | AE9: 49075100017964 | AI9: 419338.34 | AJ9: 421363.69 | AK9: 425205.32 | AL9: 428284.15 | AM9: 432502.22 | AN9: 437551.12 | AO9: 442424.09 | AP9: 447047.46 | AQ9: 0 | AR9: 0 | AS9: 0 | AT9: 0 | AU9: 0 | AV9: 0 | AW9: 0 | AX9: 0 | AY9: 0 | AZ9: {=XLOOKUP(C9,'PL TOTAL D0'!K:K,'PL TOTAL D0'!L:L,"")}
A10: XP | B10: Alessandra Carneiro Macedo | C10: 19806802 | D10: Investeseg | E10: BA | F10: Murilo Silva | G10: =IFS($AZ$3:$AZ$993<=250000,"David",$AZ$3:$AZ$993<=800000,"Gabriel", $AZ$3:$AZ$993>800000,"Marcus") -> David | H10: Pode Operar | I10: ------ | J10: =IF(Q10=0,"Não","Sim") -> Sim | K10: 46237 | M10: CON | N10: 0.012 | O10: ------ | P10: 0 | Q10: Mínimo 80% em RF, até 10% em Ações e até 10% em FIIs (04/08/2026) | S10: PF | T10: 873.300.835-34 | U10: 71 99139-1066 | V10: sanmacedo@hotmail.com | W10: 27502 | X10: BA | Y10: =IFS(H:H="Encerrado","Encerrado",COUNTBLANK(AF10:AN10)>0,"Ativo",SUM(AF10:AN10)=0,"Inativo",SUM(AF10:AN10)>0,"Ativo") -> Ativo | AA10: Moderado
A11: XP | B11: Alessandra Sado | C11: 3437690 | D11: VcInvest | E11: GO | F11: Bruno Ribeiro | G11: =IFS($AZ$3:$AZ$993<=250000,"David",$AZ$3:$AZ$993<=800000,"Gabriel", $AZ$3:$AZ$993>800000,"Marcus") -> David | H11: Inativo | I11: STVM Saída | J11: =IF(Q11=0,"Não","Sim") -> Sim | K11: 45784 | M11: INC | N11: 0.012 | O11: ------ | P11: 0 | Q11: 100K D+0 (25/09/2025) | S11: PF | T11: 788.043.611-15 | U11: (62) - 981390612 | V11: alessandrasado@gmail.com | W11: 27672 | X11: GO | Y11: =IFS(H:H="Encerrado","Encerrado",COUNTBLANK(AF11:AN11)>0,"Ativo",SUM(AF11:AN11)=0,"Inativo",SUM(AF11:AN11)>0,"Ativo") -> Ativo | AA11: Moderado | AD11: 45784 | AE11: 49075100018881 | AL11: 296761.76 | AM11: 381929.51 | AN11: 387089.81 | AO11: 463084.67 | AP11: 764733.3 | AQ11: 998361.6 | AR11: 1017662.9 | AS11: 1063337.8 | AT11: 1187509.4 | AU11: 1226246.6 | AV11: 1231186.8 | AW11: 1254526.1 | AX11: 309501.7 | AY11: 84.71 | AZ11: {=XLOOKUP(C11,'PL TOTAL D0'!K:K,'PL TOTAL D0'!L:L,"")} -> 84.71
A12: XP | B12: Alessandra Gomes Moreira | C12: 17005019 | D12: Bluemetrix | E12: GO | F12: Felipe Rios | G12: =IFS($AZ$3:$AZ$993<=250000,"David",$AZ$3:$AZ$993<=800000,"Gabriel", $AZ$3:$AZ$993>800000,"Marcus") -> David | H12: Ativo | I12: ------ | J12: =IF(Q12=0,"Não","Sim") -> Não | K12: 45883 | M12: INC | N12: 0.012 | O12: ------ | P12: 0 | S12: PF | T12: 017.663.181-00 | U12: (62) - 98114-3812 | V12: ales232009@hotmail.com | W12: 31485 | X12: GO | Y12: =IFS(H:H="Encerrado","Encerrado",COUNTBLANK(AF12:AN12)>0,"Ativo",SUM(AF12:AN12)=0,"Inativo",SUM(AF12:AN12)>0,"Ativo") -> Ativo | AD12: 45883 | AE12: 49075100019312 | AN12: 46050.75 | AO12: 46603.716 | AP12: 47377.363 | AQ12: 42288.847 | AR12: 46492.169 | AS12: 45078.08 | AT12: 62809.19 | AU12: 61457.708 | AV12: 59178.075 | AW12: 60048.97 | AX12: 57448.968 | AY12: 51003.349 | AZ12: {=XLOOKUP(C12,'PL TOTAL D0'!K:K,'PL TOTAL D0'!L:L,"")} -> 51878.17
